<?xml version="1.0"?>
<robot xmlns:xacro="http://www.ros.org/wiki/xacro" name="allegro_hand_right">
<link name="palm_link">
<visual>
<origin xyz="0 0.034 -0.002" rpy="3.14159 -0 0" />
<geometry>
<mesh filename="package://allegro_hand_description/meshes/g_r2.stl"/>
</geometry>
<material name="g_r2_material">
<color rgba="0.2 0.2 0.2 1.0"/>
</material>
</visual>
<collision>
<origin xyz="0 0.034 -0.002" rpy="3.14159 -0 0" />
<geometry>
<mesh filename="package://allegro_hand_description/meshes/g_r2.stl"/>
</geometry>
<material name="g_r2_material">
<color rgba="0.2 0.2 0.2 1.0"/>
</material>
</collision>
<inertial>
<origin xyz="-0.00043535 0.0160404 -0.0404815" rpy="0 0 0"/>
<mass value="0.404445" />
<inertia ixx="0.000491371" ixy="-9.01723e-06"  ixz="1.17974e-05" iyy="0.000773265" iyz="-5.50867e-06" izz="0.000547843" />
</inertial>
</link>

<link name="link_0">
<visual>
<origin xyz="0 0 -0.0152" rpy="1.5708 -0 0" />
<geometry>
<mesh filename="package://allegro_hand_description/meshes/extended_finger_base.stl"/>
</geometry>
<material name="extended_finger_base_material">
<color rgba="0.647059 0.647059 0.647059 1.0"/>
</material>
</visual>
<collision>
<origin xyz="0 0 -0.0152" rpy="1.5708 -0 0" />
<geometry>
<mesh filename="package://allegro_hand_description/meshes/extended_finger_base.stl"/>
</geometry>
<material name="extended_finger_base_material">
<color rgba="0.647059 0.647059 0.647059 1.0"/>
</material>
</collision>
<inertial>
<origin xyz="-0.00041342 0.000666149 0.00960564" rpy="0 0 0"/>
<mass value="0.0136672" />
<inertia ixx="2.13441e-06" ixy="5.86704e-10"  ixz="-7.9563e-08" iyy="1.24411e-06" iyz="-6.13056e-08" izz="1.671e-06" />
</inertial>
</link>

<link name="link_1">
<visual>
<origin xyz="-0.0182688 0 -0.0317805" rpy="4.97195e-33 1.48353 3.14159" />
<geometry>
<mesh filename="package://allegro_hand_description/meshes/p2_r6.stl"/>
</geometry>
<material name="p2_r6_material">
<color rgba="0.129412 0.129412 0.129412 1.0"/>
</material>
</visual>
<collision>
<origin xyz="-0.0182688 0 -0.0317805" rpy="4.97195e-33 1.48353 3.14159" />
<geometry>
<mesh filename="package://allegro_hand_description/meshes/p2_r6.stl"/>
</geometry>
<material name="p2_r6_material">
<color rgba="0.129412 0.129412 0.129412 1.0"/>
</material>
</collision>
<inertial>
<origin xyz="0.027 9.54536e-05 0.0124409" rpy="0 0 0"/>
<mass value="0.0418346" />
<inertia ixx="4.00114e-06" ixy="-1.81985e-08"  ixz="-4.42841e-15" iyy="1.97927e-05" iyz="1.59578e-08" izz="1.88563e-05" />
</inertial>
</link>

<link name="link_2">
<visual>
<origin xyz="0.0722688 -4.16334e-17 -0.0317805" rpy="-7.73415e-32 1.48353 2.48382e-32" />
<geometry>
<mesh filename="package://allegro_hand_description/meshes/extended_fingertop.stl"/>
</geometry>
<material name="extended_fingertop_material">
<color rgba="0.647059 0.647059 0.647059 1.0"/>
</material>
</visual>
<collision>
<origin xyz="0.0722688 -4.16334e-17 -0.0317805" rpy="-7.73415e-32 1.48353 2.48382e-32" />
<geometry>
<mesh filename="package://allegro_hand_description/meshes/extended_fingertop.stl"/>
</geometry>
<material name="extended_fingertop_material">
<color rgba="0.647059 0.647059 0.647059 1.0"/>
</material>
</collision>
<inertial>
<origin xyz="-0.0294592 -0.000104104 0.0123435" rpy="0 0 0"/>
<mass value="0.0318021" />
<inertia ixx="3.48619e-06" ixy="1.20808e-07"  ixz="6.2918e-07" iyy="8.82437e-06" iyz="5.78644e-09" izz="7.34771e-06" />
</inertial>
</link>

<link name="link_3">
<visual>
<origin xyz="0.1253 -5.55112e-17 0.0118" rpy="-3.14159 -2.34013e-31 -1.5708" />
<geometry>
<mesh filename="package://allegro_hand_description/meshes/p4_r.stl"/>
</geometry>
<material name="p4_r_material">
<color rgba="0.129412 0.129412 0.129412 1.0"/>
</material>
</visual>
<collision>
<origin xyz="0.1253 -5.55112e-17 0.0118" rpy="-3.14159 -2.34013e-31 -1.5708" />
<geometry>
<mesh filename="package://allegro_hand_description/meshes/p4_r.stl"/>
</geometry>
<material name="p4_r_material">
<color rgba="0.129412 0.129412 0.129412 1.0"/>
</material>
</collision>
<inertial>
<origin xyz="-0.0100051 0.000639363 0.0123057" rpy="0 0 0"/>
<mass value="0.0088374" />
<inertia ixx="1.08072e-06" ixy="-4.65695e-08"  ixz="-3.42321e-08" iyy="1.11236e-06" iyz="-8.85024e-10" izz="5.61586e-07" />
</inertial>
</link>

<joint name="joint_3_0" type="revolute">
<origin xyz="-0.04615 1.38778e-17 0.0001" rpy="1.74208e-17 1.16504e-16 -2.59095e-14" />
<parent link="link_2" />
<child link="link_3" />
<axis xyz="0 0 1"/>
<limit effort="1" velocity="20" />
<joint_properties friction="0.0"/>
</joint>

<joint name="joint_2_0" type="revolute">
<origin xyz="0.054 -3.46945e-17 0" rpy="2.49195e-17 -1.43827e-17 3.14159" />
<parent link="link_1" />
<child link="link_2" />
<axis xyz="0 0 1"/>
<limit effort="1" velocity="20" />
<joint_properties friction="0.0"/>
</joint>

<joint name="joint_1_0" type="revolute">
<origin xyz="-6.93889e-18 -0.0119 0.02545" rpy="-1.5708 -1.5708 0" />
<parent link="link_0" />
<child link="link_1" />
<axis xyz="0 0 1"/>
<limit effort="1" velocity="20" />
<joint_properties friction="0.0"/>
</joint>

<joint name="joint_0_0" type="revolute">
<origin xyz="-0.0435377 0.034 -0.00553922" rpy="-0.0872665 -0 1.5708" />
<parent link="palm_link" />
<child link="link_0" />
<axis xyz="0 0 1"/>
<limit effort="1" velocity="20" />
<joint_properties friction="0.0"/>
</joint>

<link name="link_4">
<visual>
<origin xyz="0 -2.68398e-34 -0.0152" rpy="1.5708 -0 0" />
<geometry>
<mesh filename="package://allegro_hand_description/meshes/extended_finger_base.stl"/>
</geometry>
<material name="extended_finger_base_material">
<color rgba="0.647059 0.647059 0.647059 1.0"/>
</material>
</visual>
<collision>
<origin xyz="0 -2.68398e-34 -0.0152" rpy="1.5708 -0 0" />
<geometry>
<mesh filename="package://allegro_hand_description/meshes/extended_finger_base.stl"/>
</geometry>
<material name="extended_finger_base_material">
<color rgba="0.647059 0.647059 0.647059 1.0"/>
</material>
</collision>
<inertial>
<origin xyz="-0.00041342 0.000666149 0.00960564" rpy="0 0 0"/>
<mass value="0.0136672" />
<inertia ixx="2.13441e-06" ixy="5.86704e-10"  ixz="-7.9563e-08" iyy="1.24411e-06" iyz="-6.13056e-08" izz="1.671e-06" />
</inertial>
</link>

<link name="link_5">
<visual>
<origin xyz="0.0182688 6.93889e-18 -0.0317805" rpy="-2.03514e-33 1.48353 -4.09322e-33" />
<geometry>
<mesh filename="package://allegro_hand_description/meshes/p2_r6.stl"/>
</geometry>
<material name="p2_r6_material">
<color rgba="0.129412 0.129412 0.129412 1.0"/>
</material>
</visual>
<collision>
<origin xyz="0.0182688 6.93889e-18 -0.0317805" rpy="-2.03514e-33 1.48353 -4.09322e-33" />
<geometry>
<mesh filename="package://allegro_hand_description/meshes/p2_r6.stl"/>
</geometry>
<material name="p2_r6_material">
<color rgba="0.129412 0.129412 0.129412 1.0"/>
</material>
</collision>
<inertial>
<origin xyz="-0.027 -9.54536e-05 0.0124409" rpy="0 0 0"/>
<mass value="0.0418346" />
<inertia ixx="4.44908e-06" ixy="2.0693e-08"  ixz="2.54038e-06" iyy="1.97927e-05" iyz="1.25552e-08" izz="1.84084e-05" />
</inertial>
</link>

<link name="link_6">
<visual>
<origin xyz="0.0722688 -4.85723e-17 -0.0317805" rpy="-6.57989e-33 1.48353 4.52701e-32" />
<geometry>
<mesh filename="package://allegro_hand_description/meshes/extended_fingertop.stl"/>
</geometry>
<material name="extended_fingertop_material">
<color rgba="0.647059 0.647059 0.647059 1.0"/>
</material>
</visual>
<collision>
<origin xyz="0.0722688 -4.85723e-17 -0.0317805" rpy="-6.57989e-33 1.48353 4.52701e-32" />
<geometry>
<mesh filename="package://allegro_hand_description/meshes/extended_fingertop.stl"/>
</geometry>
<material name="extended_fingertop_material">
<color rgba="0.647059 0.647059 0.647059 1.0"/>
</material>
</collision>
<inertial>
<origin xyz="-0.0294592 -0.000104104 0.0123435" rpy="0 0 0"/>
<mass value="0.0318021" />
<inertia ixx="3.48619e-06" ixy="1.20808e-07"  ixz="6.2918e-07" iyy="8.82437e-06" iyz="5.78644e-09" izz="7.34771e-06" />
</inertial>
</link>

<link name="link_7">
<visual>
<origin xyz="0.1253 -5.55112e-17 0.0118" rpy="-3.14159 -1.17613e-34 -1.5708" />
<geometry>
<mesh filename="package://allegro_hand_description/meshes/p4_r.stl"/>
</geometry>
<material name="p4_r_material">
<color rgba="0.129412 0.129412 0.129412 1.0"/>
</material>
</visual>
<collision>
<origin xyz="0.1253 -5.55112e-17 0.0118" rpy="-3.14159 -1.17613e-34 -1.5708" />
<geometry>
<mesh filename="package://allegro_hand_description/meshes/p4_r.stl"/>
</geometry>
<material name="p4_r_material">
<color rgba="0.129412 0.129412 0.129412 1.0"/>
</material>
</collision>
<inertial>
<origin xyz="-0.0100051 0.000639363 0.0123057" rpy="0 0 0"/>
<mass value="0.0088374" />
<inertia ixx="1.08072e-06" ixy="-4.65695e-08"  ixz="-3.42321e-08" iyy="1.11236e-06" iyz="-8.85024e-10" izz="5.61586e-07" />
</inertial>
</link>

<joint name="joint_7_0" type="revolute">
<origin xyz="-0.04615 6.93889e-18 0.0001" rpy="-2.25615e-28 -3.0226e-18 1.31516e-27" />
<parent link="link_6" />
<child link="link_7" />
<axis xyz="0 0 1"/>
<limit effort="1" velocity="20" />
<joint_properties friction="0.0"/>
</joint>

<joint name="joint_6_0" type="revolute">
<origin xyz="-0.054 1.38778e-17 6.93889e-17" rpy="-2.52948e-18 1.52814e-16 2.39282e-16" />
<parent link="link_5" />
<child link="link_6" />
<axis xyz="0 0 1"/>
<limit effort="1" velocity="20" />
<joint_properties friction="0.0"/>
</joint>

<joint name="joint_5_0" type="revolute">
<origin xyz="0 -0.0119 0.02545" rpy="-1.5708 1.5708 0" />
<parent link="link_4" />
<child link="link_5" />
<axis xyz="0 0 1"/>
<limit effort="1" velocity="20" />
<joint_properties friction="0.0"/>
</joint>

<joint name="joint_4_0" type="revolute">
<origin xyz="-2.68398e-34 0.034 -0.0033" rpy="0 -0 1.5708" />
<parent link="palm_link" />
<child link="link_4" />
<axis xyz="0 0 1"/>
<limit effort="1" velocity="20" />
<joint_properties friction="0.0"/>
</joint>

<link name="link_8">
<visual>
<origin xyz="0 0 -0.0152" rpy="1.5708 -0 0" />
<geometry>
<mesh filename="package://allegro_hand_description/meshes/extended_finger_base.stl"/>
</geometry>
<material name="extended_finger_base_material">
<color rgba="0.647059 0.647059 0.647059 1.0"/>
</material>
</visual>
<collision>
<origin xyz="0 0 -0.0152" rpy="1.5708 -0 0" />
<geometry>
<mesh filename="package://allegro_hand_description/meshes/extended_finger_base.stl"/>
</geometry>
<material name="extended_finger_base_material">
<color rgba="0.647059 0.647059 0.647059 1.0"/>
</material>
</collision>
<inertial>
<origin xyz="-0.00041342 0.000666149 0.00960564" rpy="0 0 0"/>
<mass value="0.0136672" />
<inertia ixx="2.13441e-06" ixy="5.86704e-10"  ixz="-7.9563e-08" iyy="1.24411e-06" iyz="-6.13056e-08" izz="1.671e-06" />
</inertial>
</link>

<link name="link_9">
<visual>
<origin xyz="0.0182688 -6.93889e-18 -0.0317805" rpy="5.17259e-32 1.48353 3.73661e-32" />
<geometry>
<mesh filename="package://allegro_hand_description/meshes/p2_r6.stl"/>
</geometry>
<material name="p2_r6_material">
<color rgba="0.129412 0.129412 0.129412 1.0"/>
</material>
</visual>
<collision>
<origin xyz="0.0182688 -6.93889e-18 -0.0317805" rpy="5.17259e-32 1.48353 3.73661e-32" />
<geometry>
<mesh filename="package://allegro_hand_description/meshes/p2_r6.stl"/>
</geometry>
<material name="p2_r6_material">
<color rgba="0.129412 0.129412 0.129412 1.0"/>
</material>
</collision>
<inertial>
<origin xyz="-0.027 -9.54536e-05 0.0124409" rpy="0 0 0"/>
<mass value="0.0418346" />
<inertia ixx="4.44908e-06" ixy="2.0693e-08"  ixz="2.54038e-06" iyy="1.97927e-05" iyz="1.25552e-08" izz="1.84084e-05" />
</inertial>
</link>

<link name="link_10">
<visual>
<origin xyz="0.0722688 -4.16334e-17 -0.0317805" rpy="3.33062e-32 1.48353 2.19454e-32" />
<geometry>
<mesh filename="package://allegro_hand_description/meshes/extended_fingertop.stl"/>
</geometry>
<material name="extended_fingertop_material">
<color rgba="0.647059 0.647059 0.647059 1.0"/>
</material>
</visual>
<collision>
<origin xyz="0.0722688 -4.16334e-17 -0.0317805" rpy="3.33062e-32 1.48353 2.19454e-32" />
<geometry>
<mesh filename="package://allegro_hand_description/meshes/extended_fingertop.stl"/>
</geometry>
<material name="extended_fingertop_material">
<color rgba="0.647059 0.647059 0.647059 1.0"/>
</material>
</collision>
<inertial>
<origin xyz="-0.0294592 -0.000104104 0.0123435" rpy="0 0 0"/>
<mass value="0.0318021" />
<inertia ixx="3.48619e-06" ixy="1.20808e-07"  ixz="6.2918e-07" iyy="8.82437e-06" iyz="5.78644e-09" izz="7.34771e-06" />
</inertial>
</link>

<link name="link_11">
<visual>
<origin xyz="0.1253 -5.55112e-17 0.0118" rpy="-3.14159 1.42221e-32 -1.5708" />
<geometry>
<mesh filename="package://allegro_hand_description/meshes/p4_r.stl"/>
</geometry>
<material name="p4_r_material">
<color rgba="0.129412 0.129412 0.129412 1.0"/>
</material>
</visual>
<collision>
<origin xyz="0.1253 -5.55112e-17 0.0118" rpy="-3.14159 1.42221e-32 -1.5708" />
<geometry>
<mesh filename="package://allegro_hand_description/meshes/p4_r.stl"/>
</geometry>
<material name="p4_r_material">
<color rgba="0.129412 0.129412 0.129412 1.0"/>
</material>
</collision>
<inertial>
<origin xyz="-0.0100051 0.000639363 0.0123057" rpy="0 0 0"/>
<mass value="0.0088374" />
<inertia ixx="1.08072e-06" ixy="-4.65695e-08"  ixz="-3.42321e-08" iyy="1.11236e-06" iyz="-8.85024e-10" izz="5.61586e-07" />
</inertial>
</link>

<joint name="joint_11_0" type="revolute">
<origin xyz="-0.04615 6.93889e-18 0.0001" rpy="1.23596e-17 -5.12367e-16 -3.01099e-15" />
<parent link="link_10" />
<child link="link_11" />
<axis xyz="0 0 1"/>
<limit effort="1" velocity="20" />
<joint_properties friction="0.0"/>
</joint>

<joint name="joint_10_0" type="revolute">
<origin xyz="-0.054 6.93889e-18 -1.11022e-16" rpy="-1.75219e-16 -7.47482e-16 5.44133e-16" />
<parent link="link_9" />
<child link="link_10" />
<axis xyz="0 0 1"/>
<limit effort="1" velocity="20" />
<joint_properties friction="0.0"/>
</joint>

<joint name="joint_9_0" type="revolute">
<origin xyz="-2.08167e-17 -0.0119 0.02545" rpy="-1.5708 1.5708 0" />
<parent link="link_8" />
<child link="link_9" />
<axis xyz="0 0 1"/>
<limit effort="1" velocity="20" />
<joint_properties friction="0.0"/>
</joint>

<joint name="joint_8_0" type="revolute">
<origin xyz="0.0435377 0.034 -0.00553922" rpy="0.0872665 -0 1.5708" />
<parent link="palm_link" />
<child link="link_8" />
<axis xyz="0 0 1"/>
<limit effort="1" velocity="20" />
<joint_properties friction="0.0"/>
</joint>

<link name="link_12">
<visual>
<origin xyz="0.0232805 -0.0182 -0.0808312" rpy="-2.48535e-33 -0.0872665 -2.25407e-32" />
<geometry>
<mesh filename="package://allegro_hand_description/meshes/f1_r.stl"/>
</geometry>
<material name="f1_r_material">
<color rgba="0.129412 0.129412 0.129412 1.0"/>
</material>
</visual>
<collision>
<origin xyz="0.0232805 -0.0182 -0.0808312" rpy="-2.48535e-33 -0.0872665 -2.25407e-32" />
<geometry>
<mesh filename="package://allegro_hand_description/meshes/f1_r.stl"/>
</geometry>
<material name="f1_r_material">
<color rgba="0.129412 0.129412 0.129412 1.0"/>
</material>
</collision>
<inertial>
<origin xyz="-0.0151161 -0.00905831 -0.0192298" rpy="0 0 0"/>
<mass value="0.0660275" />
<inertia ixx="1.44344e-05" ixy="1.24597e-06"  ixz="3.47822e-08" iyy="1.76386e-05" iyz="6.49531e-07" izz="1.41981e-05" />
</inertial>
</link>

<link name="link_13">
<visual>
<origin xyz="-3.46945e-18 0 -0.0152" rpy="1.5708 2.06898e-17 1.5708" />
<geometry>
<mesh filename="package://allegro_hand_description/meshes/extended_finger_base.stl"/>
</geometry>
<material name="extended_finger_base_material">
<color rgba="0.647059 0.647059 0.647059 1.0"/>
</material>
</visual>
<collision>
<origin xyz="-3.46945e-18 0 -0.0152" rpy="1.5708 2.06898e-17 1.5708" />
<geometry>
<mesh filename="package://allegro_hand_description/meshes/extended_finger_base.stl"/>
</geometry>
<material name="extended_finger_base_material">
<color rgba="0.647059 0.647059 0.647059 1.0"/>
</material>
</collision>
<inertial>
<origin xyz="-0.000666149 -0.00041342 0.00960564" rpy="0 0 0"/>
<mass value="0.0136672" />
<inertia ixx="1.671e-06" ixy="6.13056e-08"  ixz="7.9563e-08" iyy="1.24411e-06" iyz="5.86704e-10" izz="2.13441e-06" />
</inertial>
</link>

<link name="link_14">
<visual>
<origin xyz="0.0787805 -0.0716312 0.0251" rpy="-1.5708 -6.24879e-32 0.0872665" />
<geometry>
<mesh filename="package://allegro_hand_description/meshes/f3_r.stl"/>
</geometry>
<material name="f3_r_material">
<color rgba="0.129412 0.129412 0.129412 1.0"/>
</material>
</visual>
<collision>
<origin xyz="0.0787805 -0.0716312 0.0251" rpy="-1.5708 -6.24879e-32 0.0872665" />
<geometry>
<mesh filename="package://allegro_hand_description/meshes/f3_r.stl"/>
</geometry>
<material name="f3_r_material">
<color rgba="0.129412 0.129412 0.129412 1.0"/>
</material>
</collision>
<inertial>
<origin xyz="-0.0169218 0.00050045 0.012098" rpy="0 0 0"/>
<mass value="0.0307701" />
<inertia ixx="3.26297e-06" ixy="-7.80105e-07"  ixz="4.19183e-07" iyy="9.45316e-06" iyz="7.40454e-08" izz="8.27249e-06" />
</inertial>
</link>

<link name="link_15">
<visual>
<origin xyz="0.13018 -0.0716312 0.0252" rpy="-1.5708 -4.16204e-32 0.0872665" />
<geometry>
<mesh filename="package://allegro_hand_description/meshes/f4_r.stl"/>
</geometry>
<material name="f4_r_material">
<color rgba="0.2 0.2 0.2 1.0"/>
</material>
</visual>
<collision>
<origin xyz="0.13018 -0.0716312 0.0252" rpy="-1.5708 -4.16204e-32 0.0872665" />
<geometry>
<mesh filename="package://allegro_hand_description/meshes/f4_r.stl"/>
</geometry>
<material name="f4_r_material">
<color rgba="0.2 0.2 0.2 1.0"/>
</material>
</collision>
<inertial>
<origin xyz="-0.0146717 0.000106021 0.012196" rpy="0 0 0"/>
<mass value="0.0326938" />
<inertia ixx="2.85763e-06" ixy="-2.76566e-07"  ixz="3.76274e-07" iyy="6.11217e-06" iyz="5.74019e-08" izz="5.36876e-06" />
</inertial>
</link>

<joint name="joint_15_0" type="revolute">
<origin xyz="-0.0514 -9.00668e-15 -0.0001" rpy="-4.53557e-16 3.39461e-16 2.07948e-13" />
<parent link="link_14" />
<child link="link_15" />
<axis xyz="0 0 1"/>
<limit effort="1" velocity="20" />
<joint_properties friction="0.0"/>
</joint>

<joint name="joint_14_0" type="revolute">
<origin xyz="0.0119 -1.38778e-17 0.02545" rpy="3.14159 1.5708 0" />
<parent link="link_13" />
<child link="link_14" />
<axis xyz="0 0 1"/>
<limit effort="1" velocity="20" />
<joint_properties friction="0.0"/>
</joint>

<joint name="joint_13_0" type="revolute">
<origin xyz="-0.0375 -0.005 -0.0092" rpy="-1.5708 -3.01469e-15 1.5708" />
<parent link="link_12" />
<child link="link_13" />
<axis xyz="0 0 1"/>
<limit effort="1" velocity="20" />
<joint_properties friction="0.0"/>
</joint>

<joint name="joint_12_0" type="revolute">
<origin xyz="-0.0161208 0.0158 -0.0848515" rpy="-3.14159 -0.0872665 1.84398e-16" />
<parent link="palm_link" />
<child link="link_12" />
<axis xyz="0 0 1"/>
<limit effort="1" velocity="20" />
<joint_properties friction="0.0"/>
</joint>

    <!-- ============================================================================= -->

</robot>

