<?xml version="1.0"?>
<robot xmlns:xacro="http://www.ros.org/wiki/xacro" name="allegro_hand_right">
<link name="palm_link">
<visual>
<origin xyz="0 0.034 -0.002" rpy="3.14159 -0 0" />
<geometry>
<mesh filename="package://allegro_hand_description/meshes/g_r2.stl"/>
</geometry>
<material name="g_r2_material">
<color rgba="0.2 0.2 0.2 1.0"/>
</material>
</visual>
<collision>
<origin xyz="0 0.034 -0.002" rpy="3.14159 -0 0" />
<geometry>
<mesh filename="package://allegro_hand_description/meshes/g_r2.stl"/>
</geometry>
<material name="g_r2_material">
<color rgba="0.2 0.2 0.2 1.0"/>
</material>
</collision>
<inertial>
<origin xyz="-0.00043535 0.0160404 -0.0404815" rpy="0 0 0"/>
<mass value="0.404445" />
<inertia ixx="0.000491371" ixy="-9.01723e-06"  ixz="1.17974e-05" iyy="0.000773265" iyz="-5.50867e-06" izz="0.000547843" />
</inertial>
</link>

<link name="link_12">
<visual>
<origin xyz="0.0232805 -0.0182 -0.0808312" rpy="2.80795e-33 -0.0872665 1.67654e-32" />
<geometry>
<mesh filename="package://allegro_hand_description/meshes/f1_r.stl"/>
</geometry>
<material name="f1_r_material">
<color rgba="0.129412 0.129412 0.129412 1.0"/>
</material>
</visual>
<collision>
<origin xyz="0.0232805 -0.0182 -0.0808312" rpy="2.80795e-33 -0.0872665 1.67654e-32" />
<geometry>
<mesh filename="package://allegro_hand_description/meshes/f1_r.stl"/>
</geometry>
<material name="f1_r_material">
<color rgba="0.129412 0.129412 0.129412 1.0"/>
</material>
</collision>
<inertial>
<origin xyz="-0.0151161 -0.00905831 -0.0192298" rpy="0 0 0"/>
<mass value="0.0660275" />
<inertia ixx="1.44344e-05" ixy="1.24597e-06"  ixz="3.47822e-08" iyy="1.76386e-05" iyz="6.49531e-07" izz="1.41981e-05" />
</inertial>
</link>

<link name="link_13">
<visual>
<origin xyz="-0.0716312 -0.0132 -0.0610805" rpy="0 1.48353 0" />
<geometry>
<mesh filename="package://allegro_hand_description/meshes/f2_r.stl"/>
</geometry>
<material name="f2_r_material">
<color rgba="0.2 0.2 0.2 1.0"/>
</material>
</visual>
<collision>
<origin xyz="-0.0716312 -0.0132 -0.0610805" rpy="0 1.48353 0" />
<geometry>
<mesh filename="package://allegro_hand_description/meshes/f2_r.stl"/>
</geometry>
<material name="f2_r_material">
<color rgba="0.2 0.2 0.2 1.0"/>
</material>
</collision>
<inertial>
<origin xyz="0.000559654 -0.000382796 0.00686189" rpy="0 0 0"/>
<mass value="0.0100961" />
<inertia ixx="1.17617e-06" ixy="-7.33262e-09"  ixz="-6.06691e-08" iyy="6.27655e-07" iyz="-3.57441e-08" izz="1.14264e-06" />
</inertial>
</link>

<link name="link_14">
<visual>
<origin xyz="0.0722376 -0.0782248 0.0251" rpy="-1.5708 5.71807e-32 5.1921e-18" />
<geometry>
<mesh filename="package://allegro_hand_description/meshes/f3_r.stl"/>
</geometry>
<material name="f3_r_material">
<color rgba="0.129412 0.129412 0.129412 1.0"/>
</material>
</visual>
<collision>
<origin xyz="0.0722376 -0.0782248 0.0251" rpy="-1.5708 5.71807e-32 5.1921e-18" />
<geometry>
<mesh filename="package://allegro_hand_description/meshes/f3_r.stl"/>
</geometry>
<material name="f3_r_material">
<color rgba="0.129412 0.129412 0.129412 1.0"/>
</material>
</collision>
<inertial>
<origin xyz="-0.0168138 0.00197338 0.012098" rpy="0 0 0"/>
<mass value="0.0307701" />
<inertia ixx="3.22823e-06" ixy="-7.8359e-07"  ixz="-2.21326e-08" iyy="9.45316e-06" iyz="5.77307e-09" izz="8.30723e-06" />
</inertial>
</link>

<link name="link_15">
<visual>
<origin xyz="-0.0138047 -0.00862968 -0.0042" rpy="3.14159 6.72205e-18 -5.43708e-17" />
<geometry>
<mesh filename="package://allegro_hand_description/meshes/part_1.stl"/>
</geometry>
<material name="part_1_material">
<color rgba="0.615686 0.811765 0.929412 1.0"/>
</material>
</visual>
<collision>
<origin xyz="-0.0138047 -0.00862968 -0.0042" rpy="3.14159 6.72205e-18 -5.43708e-17" />
<geometry>
<mesh filename="package://allegro_hand_description/meshes/part_1.stl"/>
</geometry>
<material name="part_1_material">
<color rgba="0.615686 0.811765 0.929412 1.0"/>
</material>
</collision>
<visual>
<origin xyz="0.123442 -0.0827046 0.0252" rpy="-1.5708 -3.34023e-32 1.08581e-18" />
<geometry>
<mesh filename="package://allegro_hand_description/meshes/f4_r.stl"/>
</geometry>
<material name="f4_r_material">
<color rgba="0.2 0.2 0.2 1.0"/>
</material>
</visual>
<collision>
<origin xyz="0.123442 -0.0827046 0.0252" rpy="-1.5708 -3.34023e-32 1.08581e-18" />
<geometry>
<mesh filename="package://allegro_hand_description/meshes/f4_r.stl"/>
</geometry>
<material name="f4_r_material">
<color rgba="0.2 0.2 0.2 1.0"/>
</material>
</collision>
<inertial>
<origin xyz="-0.0145207 0.000310987 0.0104386" rpy="0 0 0"/>
<mass value="0.0366188" />
<inertia ixx="4.14572e-06" ixy="-2.52372e-07"  ixz="1.98611e-07" iyy="7.09737e-06" iyz="-5.42291e-07" izz="5.83411e-06" />
</inertial>
</link>

<joint name="joint_15_0" type="revolute">
<origin xyz="-0.0512044 0.00447981 -0.0001" rpy="-2.55755e-16 -2.42294e-15 -0.00112199" />
<parent link="link_14" />
<child link="link_15" />
<axis xyz="0 0 1"/>
<limit effort="1" velocity="20" />
<joint_properties friction="0.0"/>
</joint>

<joint name="joint_14_0" type="revolute">
<origin xyz="6.6197e-15 0.0119 0.0177" rpy="1.5708 1.44891 7.21049e-15" />
<parent link="link_13" />
<child link="link_14" />
<axis xyz="0 0 1"/>
<limit effort="1" velocity="20" />
<joint_properties friction="0.0"/>
</joint>

<joint name="joint_13_0" type="revolute">
<origin xyz="-0.0375 -0.005 -0.0092" rpy="9.18483e-17 -1.5708 0" />
<parent link="link_12" />
<child link="link_13" />
<axis xyz="0 0 1"/>
<limit effort="1" velocity="20" />
<joint_properties friction="0.0"/>
</joint>

<joint name="joint_12_0" type="revolute">
<origin xyz="-0.0161208 0.0158 -0.0848515" rpy="-3.14159 -0.0872665 9.21991e-17" />
<parent link="palm_link" />
<child link="link_12" />
<axis xyz="0 0 1"/>
<limit effort="1" velocity="20" />
<joint_properties friction="0.0"/>
</joint>

<link name="link_4">
<visual>
<origin xyz="2.68398e-34 0 -0.0152" rpy="1.5708 -0 1.5708" />
<geometry>
<mesh filename="package://allegro_hand_description/meshes/p1_r.stl"/>
</geometry>
<material name="p1_r_material">
<color rgba="0.2 0.2 0.2 1.0"/>
</material>
</visual>
<collision>
<origin xyz="2.68398e-34 0 -0.0152" rpy="1.5708 -0 1.5708" />
<geometry>
<mesh filename="package://allegro_hand_description/meshes/p1_r.stl"/>
</geometry>
<material name="p1_r_material">
<color rgba="0.2 0.2 0.2 1.0"/>
</material>
</collision>
<inertial>
<origin xyz="-0.000382796 -0.000559654 0.00686189" rpy="0 0 0"/>
<mass value="0.0100961" />
<inertia ixx="1.1229e-06" ixy="3.64743e-08"  ixz="5.12761e-08" iyy="6.27655e-07" iyz="-1.01433e-09" izz="1.19591e-06" />
</inertial>
</link>

<link name="link_5">
<visual>
<origin xyz="0.0182688 0 -0.0317805" rpy="-2.00312e-32 1.48353 1.09776e-18" />
<geometry>
<mesh filename="package://allegro_hand_description/meshes/p2_r6.stl"/>
</geometry>
<material name="p2_r6_material">
<color rgba="0.129412 0.129412 0.129412 1.0"/>
</material>
</visual>
<collision>
<origin xyz="0.0182688 0 -0.0317805" rpy="-2.00312e-32 1.48353 1.09776e-18" />
<geometry>
<mesh filename="package://allegro_hand_description/meshes/p2_r6.stl"/>
</geometry>
<material name="p2_r6_material">
<color rgba="0.129412 0.129412 0.129412 1.0"/>
</material>
</collision>
<inertial>
<origin xyz="-0.027 -9.54536e-05 0.0124409" rpy="0 0 0"/>
<mass value="0.0418346" />
<inertia ixx="4.44908e-06" ixy="2.0693e-08"  ixz="2.54038e-06" iyy="1.97927e-05" iyz="1.25552e-08" izz="1.84084e-05" />
</inertial>
</link>

<link name="link_6">
<visual>
<origin xyz="0.0722688 -4.16334e-17 -0.0317805" rpy="2.02528e-31 1.48353 2.66151e-19" />
<geometry>
<mesh filename="package://allegro_hand_description/meshes/p3_r.stl"/>
</geometry>
<material name="p3_r_material">
<color rgba="0.129412 0.129412 0.129412 1.0"/>
</material>
</visual>
<collision>
<origin xyz="0.0722688 -4.16334e-17 -0.0317805" rpy="2.02528e-31 1.48353 2.66151e-19" />
<geometry>
<mesh filename="package://allegro_hand_description/meshes/p3_r.stl"/>
</geometry>
<material name="p3_r_material">
<color rgba="0.129412 0.129412 0.129412 1.0"/>
</material>
</collision>
<inertial>
<origin xyz="-0.0242999 -0.000141902 0.0121768" rpy="0 0 0"/>
<mass value="0.0283229" />
<inertia ixx="2.7954e-06" ixy="6.90414e-08"  ixz="4.82046e-07" iyy="6.27689e-06" iyz="1.52266e-08" izz="5.2771e-06" />
</inertial>
</link>

<link name="link_7">
<visual>
<origin xyz="0.1253 -6.93889e-17 0.0118" rpy="3.14159 1.17404e-33 -1.5708" />
<geometry>
<mesh filename="package://allegro_hand_description/meshes/p4_r.stl"/>
</geometry>
<material name="p4_r_material">
<color rgba="0.129412 0.129412 0.129412 1.0"/>
</material>
</visual>
<collision>
<origin xyz="0.1253 -6.93889e-17 0.0118" rpy="3.14159 1.17404e-33 -1.5708" />
<geometry>
<mesh filename="package://allegro_hand_description/meshes/p4_r.stl"/>
</geometry>
<material name="p4_r_material">
<color rgba="0.129412 0.129412 0.129412 1.0"/>
</material>
</collision>
<inertial>
<origin xyz="-0.0100051 0.000639363 0.0123057" rpy="0 0 0"/>
<mass value="0.0088374" />
<inertia ixx="1.08072e-06" ixy="-4.65695e-08"  ixz="-3.42321e-08" iyy="1.11236e-06" iyz="-8.85024e-10" izz="5.61586e-07" />
</inertial>
</link>

<joint name="joint_7_0" type="revolute">
<origin xyz="-0.0384 3.46945e-17 0.0001" rpy="1.01082e-16 9.78124e-17 0.0201849" />
<parent link="link_6" />
<child link="link_7" />
<axis xyz="0 0 1"/>
<limit effort="1" velocity="20" />
<joint_properties friction="0.0"/>
</joint>

<joint name="joint_6_0" type="revolute">
<origin xyz="-0.054 6.93889e-18 -4.16334e-17" rpy="-6.72036e-17 -1.03227e-16 -0.0155576" />
<parent link="link_5" />
<child link="link_6" />
<axis xyz="0 0 1"/>
<limit effort="1" velocity="20" />
<joint_properties friction="0.0"/>
</joint>

<joint name="joint_5_0" type="revolute">
<origin xyz="0.0119 -1.38778e-17 0.0177" rpy="-1.5708 1.55962 1.5708" />
<parent link="link_4" />
<child link="link_5" />
<axis xyz="0 0 1"/>
<limit effort="1" velocity="20" />
<joint_properties friction="0.0"/>
</joint>

<joint name="joint_4_0" type="revolute">
<origin xyz="-2.68398e-34 0.034 -0.0033" rpy="0 -0 0" />
<parent link="palm_link" />
<child link="link_4" />
<axis xyz="0 0 1"/>
<limit effort="1" velocity="20" />
<joint_properties friction="0.0"/>
</joint>

<link name="link_8">
<visual>
<origin xyz="6.93889e-18 0 -0.0152" rpy="1.5708 -4.13046e-33 1.5708" />
<geometry>
<mesh filename="package://allegro_hand_description/meshes/p1_r.stl"/>
</geometry>
<material name="p1_r_material">
<color rgba="0.2 0.2 0.2 1.0"/>
</material>
</visual>
<collision>
<origin xyz="6.93889e-18 0 -0.0152" rpy="1.5708 -4.13046e-33 1.5708" />
<geometry>
<mesh filename="package://allegro_hand_description/meshes/p1_r.stl"/>
</geometry>
<material name="p1_r_material">
<color rgba="0.2 0.2 0.2 1.0"/>
</material>
</collision>
<inertial>
<origin xyz="-0.000382796 -0.000559654 0.00686189" rpy="0 0 0"/>
<mass value="0.0100961" />
<inertia ixx="1.1229e-06" ixy="3.64743e-08"  ixz="5.12761e-08" iyy="6.27655e-07" iyz="-1.01433e-09" izz="1.19591e-06" />
</inertial>
</link>

<link name="link_9">
<visual>
<origin xyz="0.0182688 0 -0.0317805" rpy="4.3965e-18 1.48353 -2.25901e-17" />
<geometry>
<mesh filename="package://allegro_hand_description/meshes/p2_r6.stl"/>
</geometry>
<material name="p2_r6_material">
<color rgba="0.129412 0.129412 0.129412 1.0"/>
</material>
</visual>
<collision>
<origin xyz="0.0182688 0 -0.0317805" rpy="4.3965e-18 1.48353 -2.25901e-17" />
<geometry>
<mesh filename="package://allegro_hand_description/meshes/p2_r6.stl"/>
</geometry>
<material name="p2_r6_material">
<color rgba="0.129412 0.129412 0.129412 1.0"/>
</material>
</collision>
<inertial>
<origin xyz="-0.027 -9.54536e-05 0.0124409" rpy="0 0 0"/>
<mass value="0.0418346" />
<inertia ixx="4.44908e-06" ixy="2.0693e-08"  ixz="2.54038e-06" iyy="1.97927e-05" iyz="1.25552e-08" izz="1.84084e-05" />
</inertial>
</link>

<link name="link_10">
<visual>
<origin xyz="0.0722688 -4.85723e-17 -0.0317805" rpy="-6.35473e-18 1.48353 -2.42354e-17" />
<geometry>
<mesh filename="package://allegro_hand_description/meshes/p3_r.stl"/>
</geometry>
<material name="p3_r_material">
<color rgba="0.129412 0.129412 0.129412 1.0"/>
</material>
</visual>
<collision>
<origin xyz="0.0722688 -4.85723e-17 -0.0317805" rpy="-6.35473e-18 1.48353 -2.42354e-17" />
<geometry>
<mesh filename="package://allegro_hand_description/meshes/p3_r.stl"/>
</geometry>
<material name="p3_r_material">
<color rgba="0.129412 0.129412 0.129412 1.0"/>
</material>
</collision>
<inertial>
<origin xyz="-0.0242999 -0.000141902 0.0121768" rpy="0 0 0"/>
<mass value="0.0283229" />
<inertia ixx="2.7954e-06" ixy="6.90414e-08"  ixz="4.82046e-07" iyy="6.27689e-06" iyz="1.52266e-08" izz="5.2771e-06" />
</inertial>
</link>

<link name="link_11">
<visual>
<origin xyz="0.1253 -5.55112e-17 0.0118" rpy="3.14159 4.43119e-20 -1.5708" />
<geometry>
<mesh filename="package://allegro_hand_description/meshes/p4_r.stl"/>
</geometry>
<material name="p4_r_material">
<color rgba="0.129412 0.129412 0.129412 1.0"/>
</material>
</visual>
<collision>
<origin xyz="0.1253 -5.55112e-17 0.0118" rpy="3.14159 4.43119e-20 -1.5708" />
<geometry>
<mesh filename="package://allegro_hand_description/meshes/p4_r.stl"/>
</geometry>
<material name="p4_r_material">
<color rgba="0.129412 0.129412 0.129412 1.0"/>
</material>
</collision>
<inertial>
<origin xyz="-0.0100051 0.000639363 0.0123057" rpy="0 0 0"/>
<mass value="0.0088374" />
<inertia ixx="1.08072e-06" ixy="-4.65695e-08"  ixz="-3.42321e-08" iyy="1.11236e-06" iyz="-8.85024e-10" izz="5.61586e-07" />
</inertial>
</link>

<joint name="joint_11_0" type="revolute">
<origin xyz="-0.0384 2.08167e-17 0.0001" rpy="-2.80229e-17 3.42112e-17 -8.84851e-18" />
<parent link="link_10" />
<child link="link_11" />
<axis xyz="0 0 1"/>
<limit effort="1" velocity="20" />
<joint_properties friction="0.0"/>
</joint>

<joint name="joint_10_0" type="revolute">
<origin xyz="-0.054 3.46945e-17 6.93889e-18" rpy="-2.21584e-19 4.77483e-17 -4.44754e-18" />
<parent link="link_9" />
<child link="link_10" />
<axis xyz="0 0 1"/>
<limit effort="1" velocity="20" />
<joint_properties friction="0.0"/>
</joint>

<joint name="joint_9_0" type="revolute">
<origin xyz="0.0119 -6.93889e-18 0.0177" rpy="1.5708 1.52453 -1.5708" />
<parent link="link_8" />
<child link="link_9" />
<axis xyz="0 0 1"/>
<limit effort="1" velocity="20" />
<joint_properties friction="0.0"/>
</joint>

<joint name="joint_8_0" type="revolute">
<origin xyz="0.0435377 0.034 -0.00553922" rpy="4.08095e-17 0.0872665 2.01231e-17" />
<parent link="palm_link" />
<child link="link_8" />
<axis xyz="0 0 1"/>
<limit effort="1" velocity="20" />
<joint_properties friction="0.0"/>
</joint>

<link name="link_0">
<visual>
<origin xyz="0 0 -0.0152" rpy="1.5708 -5.22937e-31 1.5708" />
<geometry>
<mesh filename="package://allegro_hand_description/meshes/p1_r.stl"/>
</geometry>
<material name="p1_r_material">
<color rgba="0.2 0.2 0.2 1.0"/>
</material>
</visual>
<collision>
<origin xyz="0 0 -0.0152" rpy="1.5708 -5.22937e-31 1.5708" />
<geometry>
<mesh filename="package://allegro_hand_description/meshes/p1_r.stl"/>
</geometry>
<material name="p1_r_material">
<color rgba="0.2 0.2 0.2 1.0"/>
</material>
</collision>
<inertial>
<origin xyz="-0.000382796 -0.000559654 0.00686189" rpy="0 0 0"/>
<mass value="0.0100961" />
<inertia ixx="1.1229e-06" ixy="3.64743e-08"  ixz="5.12761e-08" iyy="6.27655e-07" iyz="-1.01433e-09" izz="1.19591e-06" />
</inertial>
</link>

<link name="link_1">
<visual>
<origin xyz="-0.0182688 0 -0.0317805" rpy="3.86442e-29 1.48353 3.14159" />
<geometry>
<mesh filename="package://allegro_hand_description/meshes/p2_r6.stl"/>
</geometry>
<material name="p2_r6_material">
<color rgba="0.129412 0.129412 0.129412 1.0"/>
</material>
</visual>
<collision>
<origin xyz="-0.0182688 0 -0.0317805" rpy="3.86442e-29 1.48353 3.14159" />
<geometry>
<mesh filename="package://allegro_hand_description/meshes/p2_r6.stl"/>
</geometry>
<material name="p2_r6_material">
<color rgba="0.129412 0.129412 0.129412 1.0"/>
</material>
</collision>
<inertial>
<origin xyz="0.027 9.54536e-05 0.0124409" rpy="0 0 0"/>
<mass value="0.0418346" />
<inertia ixx="4.00114e-06" ixy="-1.81985e-08"  ixz="-4.42841e-15" iyy="1.97927e-05" iyz="1.59578e-08" izz="1.88563e-05" />
</inertial>
</link>

<link name="link_2">
<visual>
<origin xyz="0.0722688 -4.85723e-17 -0.0317805" rpy="4.03546e-29 1.48353 -8.89587e-29" />
<geometry>
<mesh filename="package://allegro_hand_description/meshes/p3_r.stl"/>
</geometry>
<material name="p3_r_material">
<color rgba="0.129412 0.129412 0.129412 1.0"/>
</material>
</visual>
<collision>
<origin xyz="0.0722688 -4.85723e-17 -0.0317805" rpy="4.03546e-29 1.48353 -8.89587e-29" />
<geometry>
<mesh filename="package://allegro_hand_description/meshes/p3_r.stl"/>
</geometry>
<material name="p3_r_material">
<color rgba="0.129412 0.129412 0.129412 1.0"/>
</material>
</collision>
<inertial>
<origin xyz="-0.0242999 -0.000141902 0.0121768" rpy="0 0 0"/>
<mass value="0.0283229" />
<inertia ixx="2.7954e-06" ixy="6.90414e-08"  ixz="4.82046e-07" iyy="6.27689e-06" iyz="1.52266e-08" izz="5.2771e-06" />
</inertial>
</link>

<link name="link_3">
<visual>
<origin xyz="0.1253 -6.245e-17 0.0118" rpy="3.14159 9.42337e-31 -1.5708" />
<geometry>
<mesh filename="package://allegro_hand_description/meshes/p4_r.stl"/>
</geometry>
<material name="p4_r_material">
<color rgba="0.129412 0.129412 0.129412 1.0"/>
</material>
</visual>
<collision>
<origin xyz="0.1253 -6.245e-17 0.0118" rpy="3.14159 9.42337e-31 -1.5708" />
<geometry>
<mesh filename="package://allegro_hand_description/meshes/p4_r.stl"/>
</geometry>
<material name="p4_r_material">
<color rgba="0.129412 0.129412 0.129412 1.0"/>
</material>
</collision>
<visual>
<origin xyz="-0.0157 -0.0098 0.0279" rpy="3.14159 4.53077e-16 -2.22667e-16" />
<geometry>
<mesh filename="package://allegro_hand_description/meshes/part_1.stl"/>
</geometry>
<material name="part_1_material">
<color rgba="0.615686 0.811765 0.929412 1.0"/>
</material>
</visual>
<collision>
<origin xyz="-0.0157 -0.0098 0.0279" rpy="3.14159 4.53077e-16 -2.22667e-16" />
<geometry>
<mesh filename="package://allegro_hand_description/meshes/part_1.stl"/>
</geometry>
<material name="part_1_material">
<color rgba="0.615686 0.811765 0.929412 1.0"/>
</material>
</collision>
<inertial>
<origin xyz="-0.0117565 -0.0025712 0.0171016" rpy="0 0 0"/>
<mass value="0.0127624" />
<inertia ixx="2.07875e-06" ixy="-2.08151e-07"  ixz="2.07138e-07" iyy="1.90234e-06" iyz="4.41573e-07" izz="1.01135e-06" />
</inertial>
</link>

<joint name="joint_3_0" type="revolute">
<origin xyz="-0.0384 4.16334e-17 0.0001" rpy="-4.67777e-16 4.87322e-16 -2.22667e-16" />
<parent link="link_2" />
<child link="link_3" />
<axis xyz="0 0 1"/>
<limit effort="1" velocity="20" />
<joint_properties friction="0.0"/>
</joint>

<joint name="joint_2_0" type="revolute">
<origin xyz="0.054 -2.77556e-17 6.93889e-18" rpy="4.4333e-30 -4.09865e-18 -3.14159" />
<parent link="link_1" />
<child link="link_2" />
<axis xyz="0 0 1"/>
<limit effort="1" velocity="20" />
<joint_properties friction="0.0"/>
</joint>

<joint name="joint_1_0" type="revolute">
<origin xyz="0.0119 -2.77556e-17 0.0177" rpy="4.33827e-16 -1.5708 0" />
<parent link="link_0" />
<child link="link_1" />
<axis xyz="0 0 1"/>
<limit effort="1" velocity="20" />
<joint_properties friction="0.0"/>
</joint>

<joint name="joint_0_0" type="revolute">
<origin xyz="-0.0435377 0.034 -0.00553922" rpy="-3.30132e-15 -0.0872665 3.37683e-14" />
<parent link="palm_link" />
<child link="link_0" />
<axis xyz="0 0 1"/>
<limit effort="1" velocity="20" />
<joint_properties friction="0.0"/>
</joint>

    <!-- ============================================================================= -->

</robot>

