<?xml version="1.0"?>
<robot xmlns:xacro="http://www.ros.org/wiki/xacro" name="allegro_hand_right">
<link name="palm_link">
<visual>
<origin xyz="0 0.034 -0.002" rpy="3.14159 -0 0" />
<geometry>
<mesh filename="package://allegro_hand_description/meshes/g_r2.stl"/>
</geometry>
<material name="g_r2_material">
<color rgba="0.2 0.2 0.2 1.0"/>
</material>
</visual>
<collision>
<origin xyz="0 0.034 -0.002" rpy="3.14159 -0 0" />
<geometry>
<mesh filename="package://allegro_hand_description/meshes/g_r2.stl"/>
</geometry>
<material name="g_r2_material">
<color rgba="0.2 0.2 0.2 1.0"/>
</material>
</collision>
<inertial>
<origin xyz="-0.00043535 0.0160404 -0.0404815" rpy="0 0 0"/>
<mass value="0.404445" />
<inertia ixx="0.000491371" ixy="-9.01723e-06"  ixz="1.17974e-05" iyy="0.000773265" iyz="-5.50867e-06" izz="0.000547843" />
</inertial>
</link>

<link name="link_8">
<visual>
<origin xyz="0 0 -0.0152" rpy="1.5708 -1.86697e-33 1.80877e-34" />
<geometry>
<mesh filename="package://allegro_hand_description/meshes/p1_r.stl"/>
</geometry>
<material name="p1_r_material">
<color rgba="0.2 0.2 0.2 1.0"/>
</material>
</visual>
<collision>
<origin xyz="0 0 -0.0152" rpy="1.5708 -1.86697e-33 1.80877e-34" />
<geometry>
<mesh filename="package://allegro_hand_description/meshes/p1_r.stl"/>
</geometry>
<material name="p1_r_material">
<color rgba="0.2 0.2 0.2 1.0"/>
</material>
</collision>
<inertial>
<origin xyz="-0.000559654 0.000382796 0.00686189" rpy="0 0 0"/>
<mass value="0.0100961" />
<inertia ixx="1.19591e-06" ixy="-1.01433e-09"  ixz="-5.12761e-08" iyy="6.27655e-07" iyz="-3.64743e-08" izz="1.1229e-06" />
</inertial>
</link>

<link name="link_9">
<visual>
<origin xyz="0.0722688 -2.77556e-17 -0.0317805" rpy="1.47944e-32 1.48353 1.94565e-33" />
<geometry>
<mesh filename="package://allegro_hand_description/meshes/p2_r6.stl"/>
</geometry>
<material name="p2_r6_material">
<color rgba="0.129412 0.129412 0.129412 1.0"/>
</material>
</visual>
<collision>
<origin xyz="0.0722688 -2.77556e-17 -0.0317805" rpy="1.47944e-32 1.48353 1.94565e-33" />
<geometry>
<mesh filename="package://allegro_hand_description/meshes/p2_r6.stl"/>
</geometry>
<material name="p2_r6_material">
<color rgba="0.129412 0.129412 0.129412 1.0"/>
</material>
</collision>
<inertial>
<origin xyz="0.027 -9.54536e-05 0.0124409" rpy="0 0 0"/>
<mass value="0.0418346" />
<inertia ixx="4.44908e-06" ixy="2.0693e-08"  ixz="2.54038e-06" iyy="1.97927e-05" iyz="1.25552e-08" izz="1.84084e-05" />
</inertial>
</link>

<link name="link_10">
<visual>
<origin xyz="0.0722688 -4.85723e-17 -0.0317805" rpy="-1.90013e-33 1.48353 -1.96928e-33" />
<geometry>
<mesh filename="package://allegro_hand_description/meshes/p3_r.stl"/>
</geometry>
<material name="p3_r_material">
<color rgba="0.129412 0.129412 0.129412 1.0"/>
</material>
</visual>
<collision>
<origin xyz="0.0722688 -4.85723e-17 -0.0317805" rpy="-1.90013e-33 1.48353 -1.96928e-33" />
<geometry>
<mesh filename="package://allegro_hand_description/meshes/p3_r.stl"/>
</geometry>
<material name="p3_r_material">
<color rgba="0.129412 0.129412 0.129412 1.0"/>
</material>
</collision>
<inertial>
<origin xyz="-0.0242999 -0.000141902 0.0121768" rpy="0 0 0"/>
<mass value="0.0283229" />
<inertia ixx="2.7954e-06" ixy="6.90414e-08"  ixz="4.82046e-07" iyy="6.27689e-06" iyz="1.52266e-08" izz="5.2771e-06" />
</inertial>
</link>

<link name="link_11">
<visual>
<origin xyz="5.55112e-17 0.1253 0.0118" rpy="-3.14159 8.47409e-33 -9.24446e-33" />
<geometry>
<mesh filename="package://allegro_hand_description/meshes/p4_r.stl"/>
</geometry>
<material name="p4_r_material">
<color rgba="0.129412 0.129412 0.129412 1.0"/>
</material>
</visual>
<collision>
<origin xyz="5.55112e-17 0.1253 0.0118" rpy="-3.14159 8.47409e-33 -9.24446e-33" />
<geometry>
<mesh filename="package://allegro_hand_description/meshes/p4_r.stl"/>
</geometry>
<material name="p4_r_material">
<color rgba="0.129412 0.129412 0.129412 1.0"/>
</material>
</collision>
<inertial>
<origin xyz="-0.000639363 -0.0100051 0.0123057" rpy="0 0 0"/>
<mass value="0.0088374" />
<inertia ixx="1.11236e-06" ixy="4.65695e-08"  ixz="8.85024e-10" iyy="1.08072e-06" iyz="-3.42321e-08" izz="5.61586e-07" />
</inertial>
</link>

<joint name="joint_3_0" type="revolute">
<origin xyz="-0.0384 1.38778e-17 0.0001" rpy="-2.37038e-16 -2.34535e-16 -1.5708" />
<parent link="link_10" />
<child link="link_11" />
<axis xyz="0 0 1"/>
<limit effort="1" velocity="20" />
<joint_properties friction="0.0"/>
</joint>

<joint name="joint_2_0" type="revolute">
<origin xyz="0.054 -3.46945e-17 6.93889e-18" rpy="7.82217e-20 3.01445e-17 3.14159" />
<parent link="link_9" />
<child link="link_10" />
<axis xyz="0 0 1"/>
<limit effort="1" velocity="20" />
<joint_properties friction="0.0"/>
</joint>

<joint name="joint_1_0" type="revolute">
<origin xyz="0 -0.0119 0.0177" rpy="-1.5708 -1.5708 0" />
<parent link="link_8" />
<child link="link_9" />
<axis xyz="0 0 1"/>
<limit effort="1" velocity="20" />
<joint_properties friction="0.0"/>
</joint>

<joint name="joint_0_0" type="revolute">
<origin xyz="-0.0435377 0.034 -0.00553922" rpy="-0.0872665 2.71275e-17 1.5708" />
<parent link="palm_link" />
<child link="link_8" />
<axis xyz="0 0 1"/>
<limit effort="1" velocity="20" />
<joint_properties friction="0.0"/>
</joint>

<link name="link_4">
<visual>
<origin xyz="0 -2.68398e-34 -0.0152" rpy="1.5708 -0 0" />
<geometry>
<mesh filename="package://allegro_hand_description/meshes/p1_r.stl"/>
</geometry>
<material name="p1_r_material">
<color rgba="0.2 0.2 0.2 1.0"/>
</material>
</visual>
<collision>
<origin xyz="0 -2.68398e-34 -0.0152" rpy="1.5708 -0 0" />
<geometry>
<mesh filename="package://allegro_hand_description/meshes/p1_r.stl"/>
</geometry>
<material name="p1_r_material">
<color rgba="0.2 0.2 0.2 1.0"/>
</material>
</collision>
<inertial>
<origin xyz="-0.000559654 0.000382796 0.00686189" rpy="0 0 0"/>
<mass value="0.0100961" />
<inertia ixx="1.19591e-06" ixy="-1.01433e-09"  ixz="-5.12761e-08" iyy="6.27655e-07" iyz="-3.64743e-08" izz="1.1229e-06" />
</inertial>
</link>

<link name="link_5">
<visual>
<origin xyz="0.0722688 -3.46945e-17 -0.0317805" rpy="0 1.48353 0" />
<geometry>
<mesh filename="package://allegro_hand_description/meshes/p2_r6.stl"/>
</geometry>
<material name="p2_r6_material">
<color rgba="0.129412 0.129412 0.129412 1.0"/>
</material>
</visual>
<collision>
<origin xyz="0.0722688 -3.46945e-17 -0.0317805" rpy="0 1.48353 0" />
<geometry>
<mesh filename="package://allegro_hand_description/meshes/p2_r6.stl"/>
</geometry>
<material name="p2_r6_material">
<color rgba="0.129412 0.129412 0.129412 1.0"/>
</material>
</collision>
<inertial>
<origin xyz="0.027 -9.54536e-05 0.0124409" rpy="0 0 0"/>
<mass value="0.0418346" />
<inertia ixx="4.44908e-06" ixy="2.0693e-08"  ixz="2.54038e-06" iyy="1.97927e-05" iyz="1.25552e-08" izz="1.84084e-05" />
</inertial>
</link>

<link name="link_6">
<visual>
<origin xyz="0.0722688 -4.16334e-17 -0.0317805" rpy="-4.46485e-34 1.48353 3.67136e-17" />
<geometry>
<mesh filename="package://allegro_hand_description/meshes/p3_r.stl"/>
</geometry>
<material name="p3_r_material">
<color rgba="0.129412 0.129412 0.129412 1.0"/>
</material>
</visual>
<collision>
<origin xyz="0.0722688 -4.16334e-17 -0.0317805" rpy="-4.46485e-34 1.48353 3.67136e-17" />
<geometry>
<mesh filename="package://allegro_hand_description/meshes/p3_r.stl"/>
</geometry>
<material name="p3_r_material">
<color rgba="0.129412 0.129412 0.129412 1.0"/>
</material>
</collision>
<inertial>
<origin xyz="-0.0242999 -0.000141902 0.0121768" rpy="0 0 0"/>
<mass value="0.0283229" />
<inertia ixx="2.7954e-06" ixy="6.90414e-08"  ixz="4.82046e-07" iyy="6.27689e-06" iyz="1.52266e-08" izz="5.2771e-06" />
</inertial>
</link>

<link name="link_7">
<visual>
<origin xyz="5.55112e-17 0.1253 0.0118" rpy="3.14159 -0 0" />
<geometry>
<mesh filename="package://allegro_hand_description/meshes/p4_r.stl"/>
</geometry>
<material name="p4_r_material">
<color rgba="0.129412 0.129412 0.129412 1.0"/>
</material>
</visual>
<collision>
<origin xyz="5.55112e-17 0.1253 0.0118" rpy="3.14159 -0 0" />
<geometry>
<mesh filename="package://allegro_hand_description/meshes/p4_r.stl"/>
</geometry>
<material name="p4_r_material">
<color rgba="0.129412 0.129412 0.129412 1.0"/>
</material>
</collision>
<inertial>
<origin xyz="-0.000639363 -0.0100051 0.0123057" rpy="0 0 0"/>
<mass value="0.0088374" />
<inertia ixx="1.11236e-06" ixy="4.65695e-08"  ixz="8.85024e-10" iyy="1.08072e-06" iyz="-3.42321e-08" izz="5.61586e-07" />
</inertial>
</link>

<joint name="joint_7_0" type="revolute">
<origin xyz="-0.0384 -3.46945e-18 0.0001" rpy="-1.04087e-17 4.97376e-19 -1.77487" />
<parent link="link_6" />
<child link="link_7" />
<axis xyz="0 0 1"/>
<limit effort="1" velocity="20" />
<joint_properties friction="0.0"/>
</joint>

<joint name="joint_6_0" type="revolute">
<origin xyz="0.054 -3.46945e-17 1.38778e-17" rpy="7.75011e-19 6.1992e-18 -2.93752" />
<parent link="link_5" />
<child link="link_6" />
<axis xyz="0 0 1"/>
<limit effort="1" velocity="20" />
<joint_properties friction="0.0"/>
</joint>

<joint name="joint_5_0" type="revolute">
<origin xyz="0 -0.0119 0.0177" rpy="-1.5708 -1.5708 0" />
<parent link="link_4" />
<child link="link_5" />
<axis xyz="0 0 1"/>
<limit effort="1" velocity="20" />
<joint_properties friction="0.0"/>
</joint>

<joint name="joint_4_0" type="revolute">
<origin xyz="-2.68398e-34 0.034 -0.0033" rpy="0 -0 1.5708" />
<parent link="palm_link" />
<child link="link_4" />
<axis xyz="0 0 1"/>
<limit effort="1" velocity="20" />
<joint_properties friction="0.0"/>
</joint>

<link name="link_0">
<visual>
<origin xyz="0 -6.93889e-18 -0.0152" rpy="1.5708 -1.54074e-33 -7.70372e-34" />
<geometry>
<mesh filename="package://allegro_hand_description/meshes/p1_r.stl"/>
</geometry>
<material name="p1_r_material">
<color rgba="0.2 0.2 0.2 1.0"/>
</material>
</visual>
<collision>
<origin xyz="0 -6.93889e-18 -0.0152" rpy="1.5708 -1.54074e-33 -7.70372e-34" />
<geometry>
<mesh filename="package://allegro_hand_description/meshes/p1_r.stl"/>
</geometry>
<material name="p1_r_material">
<color rgba="0.2 0.2 0.2 1.0"/>
</material>
</collision>
<inertial>
<origin xyz="-0.000559654 0.000382796 0.00686189" rpy="0 0 0"/>
<mass value="0.0100961" />
<inertia ixx="1.19591e-06" ixy="-1.01433e-09"  ixz="-5.12761e-08" iyy="6.27655e-07" iyz="-3.64743e-08" izz="1.1229e-06" />
</inertial>
</link>

<link name="link_1">
<visual>
<origin xyz="0.0722688 -2.77556e-17 -0.0317805" rpy="6.62927e-33 1.48353 2.85892e-32" />
<geometry>
<mesh filename="package://allegro_hand_description/meshes/p2_r6.stl"/>
</geometry>
<material name="p2_r6_material">
<color rgba="0.129412 0.129412 0.129412 1.0"/>
</material>
</visual>
<collision>
<origin xyz="0.0722688 -2.77556e-17 -0.0317805" rpy="6.62927e-33 1.48353 2.85892e-32" />
<geometry>
<mesh filename="package://allegro_hand_description/meshes/p2_r6.stl"/>
</geometry>
<material name="p2_r6_material">
<color rgba="0.129412 0.129412 0.129412 1.0"/>
</material>
</collision>
<inertial>
<origin xyz="0.027 -9.54536e-05 0.0124409" rpy="0 0 0"/>
<mass value="0.0418346" />
<inertia ixx="4.44908e-06" ixy="2.0693e-08"  ixz="2.54038e-06" iyy="1.97927e-05" iyz="1.25552e-08" izz="1.84084e-05" />
</inertial>
</link>

<link name="link_2">
<visual>
<origin xyz="0.0722688 -4.16334e-17 -0.0317805" rpy="-1.29854e-34 1.48353 6.03018e-34" />
<geometry>
<mesh filename="package://allegro_hand_description/meshes/p3_r.stl"/>
</geometry>
<material name="p3_r_material">
<color rgba="0.129412 0.129412 0.129412 1.0"/>
</material>
</visual>
<collision>
<origin xyz="0.0722688 -4.16334e-17 -0.0317805" rpy="-1.29854e-34 1.48353 6.03018e-34" />
<geometry>
<mesh filename="package://allegro_hand_description/meshes/p3_r.stl"/>
</geometry>
<material name="p3_r_material">
<color rgba="0.129412 0.129412 0.129412 1.0"/>
</material>
</collision>
<inertial>
<origin xyz="-0.0242999 -0.000141902 0.0121768" rpy="0 0 0"/>
<mass value="0.0283229" />
<inertia ixx="2.7954e-06" ixy="6.90414e-08"  ixz="4.82046e-07" iyy="6.27689e-06" iyz="1.52266e-08" izz="5.2771e-06" />
</inertial>
</link>

<link name="link_3">
<visual>
<origin xyz="6.245e-17 0.1253 0.0118" rpy="-3.14159 4.21297e-34 2.88889e-34" />
<geometry>
<mesh filename="package://allegro_hand_description/meshes/p4_r.stl"/>
</geometry>
<material name="p4_r_material">
<color rgba="0.129412 0.129412 0.129412 1.0"/>
</material>
</visual>
<collision>
<origin xyz="6.245e-17 0.1253 0.0118" rpy="-3.14159 4.21297e-34 2.88889e-34" />
<geometry>
<mesh filename="package://allegro_hand_description/meshes/p4_r.stl"/>
</geometry>
<material name="p4_r_material">
<color rgba="0.129412 0.129412 0.129412 1.0"/>
</material>
</collision>
<inertial>
<origin xyz="-0.000639363 -0.0100051 0.0123057" rpy="0 0 0"/>
<mass value="0.0088374" />
<inertia ixx="1.11236e-06" ixy="4.65695e-08"  ixz="8.85024e-10" iyy="1.08072e-06" iyz="-3.42321e-08" izz="5.61586e-07" />
</inertial>
</link>

<joint name="joint_11_0" type="revolute">
<origin xyz="-0.0384 2.08167e-17 0.0001" rpy="-1.96321e-17 -1.40518e-17 -1.5708" />
<parent link="link_2" />
<child link="link_3" />
<axis xyz="0 0 1"/>
<limit effort="1" velocity="20" />
<joint_properties friction="0.0"/>
</joint>

<joint name="joint_10_0" type="revolute">
<origin xyz="0.054 -2.77556e-17 -1.80411e-16" rpy="-1.00233e-17 -1.2182e-16 3.14159" />
<parent link="link_1" />
<child link="link_2" />
<axis xyz="0 0 1"/>
<limit effort="1" velocity="20" />
<joint_properties friction="0.0"/>
</joint>

<joint name="joint_9_0" type="revolute">
<origin xyz="0 -0.0119 0.0177" rpy="-1.5708 -1.5708 0" />
<parent link="link_0" />
<child link="link_1" />
<axis xyz="0 0 1"/>
<limit effort="1" velocity="20" />
<joint_properties friction="0.0"/>
</joint>

<joint name="joint_8_0" type="revolute">
<origin xyz="0.0435377 0.034 -0.00553922" rpy="0.0872665 -1.38778e-17 1.5708" />
<parent link="palm_link" />
<child link="link_0" />
<axis xyz="0 0 1"/>
<limit effort="1" velocity="20" />
<joint_properties friction="0.0"/>
</joint>

<link name="link_12">
<visual>
<origin xyz="0.0232805 -0.0182 -0.0808312" rpy="-1.40943e-18 -0.0872665 1.56769e-19" />
<geometry>
<mesh filename="package://allegro_hand_description/meshes/f1_r.stl"/>
</geometry>
<material name="f1_r_material">
<color rgba="0.129412 0.129412 0.129412 1.0"/>
</material>
</visual>
<collision>
<origin xyz="0.0232805 -0.0182 -0.0808312" rpy="-1.40943e-18 -0.0872665 1.56769e-19" />
<geometry>
<mesh filename="package://allegro_hand_description/meshes/f1_r.stl"/>
</geometry>
<material name="f1_r_material">
<color rgba="0.129412 0.129412 0.129412 1.0"/>
</material>
</collision>
<inertial>
<origin xyz="-0.0151161 -0.00905831 -0.0192298" rpy="0 0 0"/>
<mass value="0.0660275" />
<inertia ixx="1.44344e-05" ixy="1.24597e-06"  ixz="3.47822e-08" iyy="1.76386e-05" iyz="6.49531e-07" izz="1.41981e-05" />
</inertial>
</link>

<link name="link_13">
<visual>
<origin xyz="-0.0716312 -0.0132 -0.0610805" rpy="-3.99609e-16 1.48353 -3.58614e-17" />
<geometry>
<mesh filename="package://allegro_hand_description/meshes/f2_r.stl"/>
</geometry>
<material name="f2_r_material">
<color rgba="0.2 0.2 0.2 1.0"/>
</material>
</visual>
<collision>
<origin xyz="-0.0716312 -0.0132 -0.0610805" rpy="-3.99609e-16 1.48353 -3.58614e-17" />
<geometry>
<mesh filename="package://allegro_hand_description/meshes/f2_r.stl"/>
</geometry>
<material name="f2_r_material">
<color rgba="0.2 0.2 0.2 1.0"/>
</material>
</collision>
<inertial>
<origin xyz="0.000559654 -0.000382796 0.00686189" rpy="0 0 0"/>
<mass value="0.0100961" />
<inertia ixx="1.17617e-06" ixy="-7.33262e-09"  ixz="-6.06691e-08" iyy="6.27655e-07" iyz="-3.57441e-08" izz="1.14264e-06" />
</inertial>
</link>

<link name="link_14">
<visual>
<origin xyz="0.0722376 -0.0782248 0.0251" rpy="-1.5708 4.22508e-18 9.82704e-20" />
<geometry>
<mesh filename="package://allegro_hand_description/meshes/f3_r.stl"/>
</geometry>
<material name="f3_r_material">
<color rgba="0.129412 0.129412 0.129412 1.0"/>
</material>
</visual>
<collision>
<origin xyz="0.0722376 -0.0782248 0.0251" rpy="-1.5708 4.22508e-18 9.82704e-20" />
<geometry>
<mesh filename="package://allegro_hand_description/meshes/f3_r.stl"/>
</geometry>
<material name="f3_r_material">
<color rgba="0.129412 0.129412 0.129412 1.0"/>
</material>
</collision>
<inertial>
<origin xyz="-0.0168138 0.00197338 0.012098" rpy="0 0 0"/>
<mass value="0.0307701" />
<inertia ixx="3.22823e-06" ixy="-7.8359e-07"  ixz="-2.21326e-08" iyy="9.45316e-06" iyz="5.77307e-09" izz="8.30723e-06" />
</inertial>
</link>

<link name="link_15">
<visual>
<origin xyz="0.123442 -0.0827046 0.0252" rpy="-1.5708 -1.66027e-17 1.34396e-18" />
<geometry>
<mesh filename="package://allegro_hand_description/meshes/f4_r.stl"/>
</geometry>
<material name="f4_r_material">
<color rgba="0.2 0.2 0.2 1.0"/>
</material>
</visual>
<collision>
<origin xyz="0.123442 -0.0827046 0.0252" rpy="-1.5708 -1.66027e-17 1.34396e-18" />
<geometry>
<mesh filename="package://allegro_hand_description/meshes/f4_r.stl"/>
</geometry>
<material name="f4_r_material">
<color rgba="0.2 0.2 0.2 1.0"/>
</material>
</collision>
<inertial>
<origin xyz="-0.0146067 0.00138434 0.012196" rpy="0 0 0"/>
<mass value="0.0326938" />
<inertia ixx="2.81137e-06" ixy="-2.80516e-07"  ixz="1.52531e-07" iyy="6.11217e-06" iyz="3.30792e-08" izz="5.41503e-06" />
</inertial>
</link>

<joint name="joint_15_0" type="revolute">
<origin xyz="-0.0512044 0.00447981 -0.0001" rpy="5.40253e-18 -1.02529e-16 1.8333e-18" />
<parent link="link_14" />
<child link="link_15" />
<axis xyz="0 0 1"/>
<limit effort="1" velocity="20" />
<joint_properties friction="0.0"/>
</joint>

<joint name="joint_14_0" type="revolute">
<origin xyz="6.60583e-15 0.0119 0.0177" rpy="1.5708 1.48353 -3.76443e-15" />
<parent link="link_13" />
<child link="link_14" />
<axis xyz="0 0 1"/>
<limit effort="1" velocity="20" />
<joint_properties friction="0.0"/>
</joint>

<joint name="joint_13_0" type="revolute">
<origin xyz="-0.0375 -0.005 -0.0092" rpy="2.53041e-16 -1.5708 0" />
<parent link="link_12" />
<child link="link_13" />
<axis xyz="0 0 1"/>
<limit effort="1" velocity="20" />
<joint_properties friction="0.0"/>
</joint>

<joint name="joint_12_0" type="revolute">
<origin xyz="-0.0161208 0.0158 -0.0848515" rpy="-3.12 -0.0845585 -0.250381" />
<parent link="palm_link" />
<child link="link_12" />
<axis xyz="0 0 1"/>
<limit effort="1" velocity="20" />
<joint_properties friction="0.0"/>
</joint>

    <!-- ============================================================================= -->

</robot>

